<?xml version="1.0" encoding="UTF-8"?>
<!-- Generated by org.testng.reporters.JUnitReportReporter -->
<testsuite hostname="vignesh" failures="1" tests="5" name="Pack2.Test4" time="0.021" errors="0" timestamp="2025-06-27T15:07:19 IST" skipped="0">
  <testcase classname="Pack2.Test4" name="CarLoan" time="0.003"/>
  <system-out/>
  <testcase classname="Pack2.Test4" name="Xe" time="0.002"/>
  <system-out/>
  <testcase classname="Pack2.Test4" name="before2" time="0.002"/>
  <system-out/>
  <testcase classname="Pack2.Test4" name="DemoS" time="0.012">
    <failure message="expected [true] but found [false]" type="java.lang.AssertionError">
      <![CDATA[java.lang.AssertionError: expected [true] but found [false]
at org.testng.Assert.fail(Assert.java:99)
at org.testng.Assert.failNotEquals(Assert.java:1037)
at org.testng.Assert.assertTrue(Assert.java:45)
at org.testng.Assert.assertTrue(Assert.java:55)
at Pack2.Test4.DemoS(Test4.java:14)
at java.base/jdk.internal.reflect.DirectMethodHandleAccessor.invoke(DirectMethodHandleAccessor.java:103)
at java.base/java.lang.reflect.Method.invoke(Method.java:580)
at org.testng.internal.MethodInvocationHelper.invokeMethod(MethodInvocationHelper.java:133)
at org.testng.internal.InvokeMethodRunnable.runOne(InvokeMethodRunnable.java:45)
at org.testng.internal.InvokeMethodRunnable.call(InvokeMethodRunnable.java:73)
at org.testng.internal.InvokeMethodRunnable.call(InvokeMethodRunnable.java:11)
at java.base/java.util.concurrent.FutureTask.run(FutureTask.java:317)
at java.base/java.util.concurrent.ThreadPoolExecutor.runWorker(ThreadPoolExecutor.java:1144)
at java.base/java.util.concurrent.ThreadPoolExecutor$Worker.run(ThreadPoolExecutor.java:642)
at java.base/java.lang.Thread.run(Thread.java:1583)
]]>
    </failure>
  </testcase> <!-- DemoS -->
  <system-out/>
  <testcase classname="Pack2.Test4" name="Ze" time="0.002"/>
  <system-out/>
</testsuite> <!-- Pack2.Test4 -->
